<?xml version="1.0"?>
<robot xmlns:xacro="http://www.ros.org/wiki/xacro">
  <xacro:include filename="inertial_macros.xacro"/>
    <material name="white">
        <color rgba="1 1 1 1" />
    </material>
    
    <material name="orange">
        <color rgba="1 0.3 0.1 1" />
    </material>
    
    <material name="blue">
        <color rgba="0.2 0.2 1 1" />
    </material>
    
    <material name="black">
        <color rgba="0 0 0 1" />
    </material>
    <material name="red">
        <color rgba="1 0 0 1" />
    </material>

    <link name="base_link">

    </link>
    
    <joint name="base_footprint_joint" type="fixed">
      <parent link="base_link"/>
      <child link="base_footprint"/>
      <origin xyz="0 0 0" rpy="0 0 0"/>
    </joint>

    <link name="base_footprint">
    </link>

    <joint name="base_joint" type="fixed">
        <parent link="base_footprint" />
        <child link="base_link" />
        <origin xyz="0 0 1" rpy="0 0 0" />
    </joint>

    <link name="chassis">
        <visual>
            <origin xyz="0 0 0" rpy="0 0 0" />
            <geometry>
                <box size="0.8 7 0.4" />
            </geometry>
            <material name="cahassis-material">
                <color rgba="0.5271151256969157 0.5209955731953768 0.5028864580233624 1" />
            </material>
        </visual>
        <collision>
            <origin xyz="0 0 0" rpy="0 0 0" />
                <geometry>
                    <box size="0.8 7 0.4" />
                </geometry>
        </collision>
        <inertial>
            <origin xyz="0 0 0" rpy="0 0 0" />
            <mass value="1" />
            <inertia ixx="0.16666666666666666" ixy="0" ixz="0" iyy="0.16666666666666666" iyz="0" izz="0.16666666666666666" />
        </inertial>
    </link>

    <joint name="base_link_to_lidar" type="fixed">
        <parent link="chassis" />
        <child link="laser_frame" />
        <origin xyz="0 0 0.2569669071788341" rpy="0 0 0" />
    </joint>

    <link name="laser_frame">
        <visual>
            <origin xyz="0 0 0" rpy="0 0 0" />
            <geometry>
                <cylinder radius="0.333099402958804" length="0.13538975482266932" />
            </geometry>
            <material name="lidar-material">
                <color rgba="0 0 0 1" />
            </material>
        </visual>
        <collision>
            <origin xyz="0 0 0" rpy="0 0 0" />
                <geometry>
                    <cylinder radius="0.333099402958804" length="0.13538975482266932" />
                </geometry>
        </collision>
        <inertial>
            <origin xyz="0 0 0" rpy="0 0 0" />
            <mass value="1" />
            <inertia ixx="0.3333333333333333" ixy="0" ixz="0" iyy="0.5" iyz="0" izz="0.3333333333333333" />
        </inertial>
    </link>

    <gazebo reference="laser_frame">
        <material>Gazebo/Red</material>

        <sensor name="laser" type="ray">
            <pose> 0 0 0 0 0 0 </pose>
            <visualize>true</visualize>
            <update_rate>10</update_rate>
            <ray>
                <scan>
                    <horizontal>
                        <samples>360</samples>
                        <min_angle>-3.14</min_angle>
                        <max_angle>3.14</max_angle>
                    </horizontal>
                </scan>
                <range>
                    <min>0.3</min>
                    <max>12</max>
                </range>
            </ray>
            <plugin name="laser_controller" filename="libgazebo_ros_ray_sensor.so">
                <ros>
                    <argument>~/out:=scan</argument>
                </ros>
                <output_type>sensor_msgs/LaserScan</output_type>
                <frame_name>laser_frame</frame_name>
            </plugin>
        </sensor>
    </gazebo>



  <joint name="right_wheel_joint" type="continuous">
    <parent link="chassis" />
    <child link="right_wheel" />
    <origin xyz="-1.2 3 -0.4" rpy="1.5707963267948963 0 0" />
    <axis xyz="0 0 1"/>
  </joint>
  <link name="right_wheel">
    <visual>
      <origin xyz="0 0 0" rpy="0 0 0" />
      <geometry>
        <cylinder radius="0.6" length="0.2" />
      </geometry>
      <material name="right_wheel-material">
        <color rgba="0.6375968739867731 0.04373502925049377 0.008023192982520563 1" />
      </material>
    </visual>
    <collision>
      <origin xyz="0 0 0" rpy="0 0 0" />
      <geometry>
        <cylinder radius="0.6" length="0.2" />
      </geometry>
    </collision>
    <inertial>
      <origin xyz="0 0 0" rpy="0 0 0" />
      <mass value="1" />
      <inertia ixx="0.3333333333333333" ixy="0" ixz="0" iyy="0.5" iyz="0" izz="0.3333333333333333" />
    </inertial>
  </link>
  <joint name="base_link_to_omniwheel" type="fixed">
    <parent link="chassis" />
    <child link="omniwheel" />
    <origin xyz="13.5 -3.3 -0.7" rpy="0 0 0" />
  </joint>
  <link name="omniwheel">
    <visual>
      <origin xyz="0 0 0" rpy="0 0 0" />
      <geometry>
        <sphere radius="0.2" />
      </geometry>
      <material name="omniwheel-material">
        <color rgba="0.14702726648767014 0.10461648408208657 0.4969329950515914 1" />
      </material>
    </visual>
    <collision>
      <origin xyz="0 0 0" rpy="0 0 0" />
      <geometry>
        <sphere radius="0.2" />
      </geometry>
    </collision>
    <inertial>
      <origin xyz="0 0 0" rpy="0 0 0" />
      <mass value="1" />
      <inertia ixx="0.4" ixy="0" ixz="0" iyy="0.4" iyz="0" izz="0.4" />
    </inertial>
  </link>
  <gazebo reference="omniwheel">
    <material>Gazebo/Black</material>
    <mu1 value="0.001"/>
    <mu2 value="0.001"/>
  </gazebo>
  <joint name="base_link_to_side1" type="fixed">
    <parent link="chassis" />
    <child link="side1" />
    <origin xyz="0 3.3 -0.4" rpy="0 0 0" />
  </joint>
  <link name="side1">
    <visual>
      <origin xyz="6 0 0" rpy="0 0 0" />
      <geometry>
        <box size="16 0.4 0.4" />
      </geometry>
      <material name="side1-material">
        <color rgba="0.5271151256969157 0.5209955731953768 0.5028864580233624 1" />
      </material>
    </visual>
    <collision>
      <origin xyz="12 0 0" rpy="0 0 0" />
      <geometry>
        <box size="16 0.4 0.4" />
      </geometry>
    </collision>
    <inertial>
      <origin xyz="12 0 0" rpy="0 0 0" />
      <mass value="1" />
      <inertia ixx="0.16666666666666666" ixy="0" ixz="0" iyy="0.16666666666666666" iyz="0" izz="0.16666666666666666" />
    </inertial>
  </link>
  <joint name="base_link_to_side2" type="fixed">
    <parent link="chassis" />
    <child link="side2" />
    <origin xyz="0 -3.3 -0.4" rpy="0 0 0" />
  </joint>
  <link name="side2">
    <visual>
      <origin xyz="6 0 0" rpy="0 0 0" />
      <geometry>
        <box size="16 0.4 0.4" />
      </geometry>
      <material name="side2-material">
        <color rgba="0.5271151256969157 0.5209955731953768 0.5028864580233624 1" />
      </material>
    </visual>
    <collision>
      <origin xyz="12 0 0" rpy="0 0 0" />
      <geometry>
        <box size="16 0.4 0.4" />
      </geometry>
    </collision>
    <inertial>
      <origin xyz="12 0 0" rpy="0 0 0" />
      <mass value="1" />
      <inertia ixx="0.16666666666666666" ixy="0" ixz="0" iyy="0.16666666666666666" iyz="0" izz="0.16666666666666666" />
    </inertial>
  </link>
  <joint name="left_wheel_joint" type="continuous">
    <parent link="chassis" />
    <child link="left_wheel" />
    <origin xyz="-1.2 -3 -0.4" rpy="1.5707963267948963 0 0" />
    <axis xyz="0 0 1"/>
  </joint>
  <link name="left_wheel">
    <visual>
      <origin xyz="0 0 0" rpy="0 0 0" />
      <geometry>
        <cylinder radius="0.6" length="0.2" />
      </geometry>
      <material name="left_wheel-material">
        <color rgba="0.6375968739867731 0.04373502925049377 0.008023192982520563 1" />
      </material>
    </visual>
    <collision>
      <origin xyz="0 0 0" rpy="0 0 0" />
      <geometry>
        <cylinder radius="0.6" length="0.2" />
      </geometry>
    </collision>
    <inertial>
      <origin xyz="0 0 0" rpy="0 0 0" />
      <mass value="1" />
      <inertia ixx="0.3333333333333333" ixy="0" ixz="0" iyy="0.5" iyz="0" izz="0.3333333333333333" />
    </inertial>
  </link>
  <joint name="base_link_to_omniwheel1" type="fixed">
    <parent link="chassis" />
    <child link="omniwheel1" />
    <origin xyz="13.5 3.3 -0.7" rpy="0 0 0" />
  </joint>
  <link name="omniwheel1">
    <visual>
      <origin xyz="0 0 0" rpy="0 0 0" />
      <geometry>
        <sphere radius="0.2" />
      </geometry>
      <material name="omniwheel1-material">
        <color rgba="0.14702726648767014 0.10461648408208657 0.4969329950515914 1" />
      </material>
    </visual>
    <collision>
      <origin xyz="0 0 0" rpy="0 0 0" />
      <geometry>
        <sphere radius="0.2" />
      </geometry>
    </collision>
    <inertial>
      <origin xyz="0 0 0" rpy="0 0 0" />
      <mass value="1" />
      <inertia ixx="0.4" ixy="0" ixz="0" iyy="0.4" iyz="0" izz="0.4" />
    </inertial>
  </link>
    <gazebo reference="omniwheel1">
    <material>Gazebo/Black</material>
    <mu1 value="0.001"/>
    <mu2 value="0.001"/>
  </gazebo>
</robot>