<?xml version="1.0"?>
<robot xmlns:xacro="http://www.ros.org/wiki/xacro">
  <link name="base_footprint"></link>
  <joint name="base_joint" type="fixed">
    <parent link="base_footprint" />
    <child link="base_link" />
    <origin xyz="0 0 1" rpy="0 0 0" />
  </joint>
  <link name="base_link">
    <visual>
      <origin xyz="0 0 0" rpy="0 0 0" />
      <geometry>
        <box size="0.8 7 0.4" />
      </geometry>
      <material name="base_link-material">
        <color rgba="0.5271151256969157 0.5209955731953768 0.5028864580233624 1" />
      </material>
    </visual>
    <collision>
      <origin xyz="0 0 0" rpy="0 0 0" />
      <geometry>
        <box size="0.8 7 0.4" />
      </geometry>
    </collision>
    <inertial>
      <origin xyz="0 0 0" rpy="0 0 0" />
      <mass value="1" />
      <inertia ixx="0.16666666666666666" ixy="0" ixz="0" iyy="0.16666666666666666" iyz="0" izz="0.16666666666666666" />
    </inertial>
  </link>
  <joint name="base_link_to_lidar" type="fixed">
    <parent link="base_link" />
    <child link="lidar" />
    <origin xyz="0 0 0.2569669071788341" rpy="0 0 0" />
  </joint>
  <link name="lidar">
    <visual>
      <origin xyz="0 0 0" rpy="0 0 0" />
      <geometry>
        <cylinder radius="0.333099402958804" length="0.13538975482266932" />
      </geometry>
      <material name="lidar-material">
        <color rgba="0 0 0 1" />
      </material>
    </visual>
    <collision>
      <origin xyz="0 0 0" rpy="0 0 0" />
      <geometry>
        <cylinder radius="0.333099402958804" length="0.13538975482266932" />
      </geometry>
    </collision>
    <inertial>
      <origin xyz="0 0 0" rpy="0 0 0" />
      <mass value="1" />
      <inertia ixx="0.3333333333333333" ixy="0" ixz="0" iyy="0.5" iyz="0" izz="0.3333333333333333" />
    </inertial>

        <sensor type="lidar" name="lidar">
            <always_on>true</always_on>
            <update_rate>5</update_rate>
            <origin>0 0 0.2569669071788341 0 0 0</origin>
            <ray>
                <scan>
                    <horizontal>
                        <samples>360</samples>
                        <resolution>1</resolution>
                        <min_angle>0</min_angle>
                        <max_angle>6.28</max_angle>
                    </horizontal>
                    <range>
                        <min>0.12</min>
                        <max>3.5</max>
                        <resolution>0.015</resolution>
                    </range>
                </scan>
                <noise>
                    <type>gaussian</type>
                    <mean>0</mean>
                    <stddev>0.01</stddev>
                </noise>
            </ray>
        </sensor>
      </link>
  <joint name="base_link_to_wheel_right" type="continuous">
    <parent link="base_link" />
    <child link="wheel_right" />
    <origin xyz="-1.2 3 -0.4" rpy="1.5707963267948963 0 0" />
    <axis xyz="0 0 1"/>
  </joint>
  <link name="wheel_right">
    <visual>
      <origin xyz="0 0 0" rpy="0 0 0" />
      <geometry>
        <cylinder radius="0.6" length="0.2" />
      </geometry>
      <material name="wheel_right-material">
        <color rgba="0.6375968739867731 0.04373502925049377 0.008023192982520563 1" />
      </material>
    </visual>
    <collision>
      <origin xyz="0 0 0" rpy="0 0 0" />
      <geometry>
        <cylinder radius="0.6" length="0.2" />
      </geometry>
    </collision>
    <inertial>
      <origin xyz="0 0 0" rpy="0 0 0" />
      <mass value="1" />
      <inertia ixx="0.3333333333333333" ixy="0" ixz="0" iyy="0.5" iyz="0" izz="0.3333333333333333" />
    </inertial>
  </link>
  <joint name="base_link_to_omniwheel" type="fixed">
    <parent link="base_link" />
    <child link="omniwheel" />
    <origin xyz="13.5 -3.3 -0.7" rpy="0 0 0" />
  </joint>
  <link name="omniwheel">
    <visual>
      <origin xyz="0 0 0" rpy="0 0 0" />
      <geometry>
        <sphere radius="0.2" />
      </geometry>
      <material name="omniwheel-material">
        <color rgba="0.14702726648767014 0.10461648408208657 0.4969329950515914 1" />
      </material>
    </visual>
    <collision>
      <origin xyz="0 0 0" rpy="0 0 0" />
      <geometry>
        <sphere radius="0.2" />
      </geometry>
    </collision>
    <inertial>
      <origin xyz="0 0 0" rpy="0 0 0" />
      <mass value="1" />
      <inertia ixx="0.4" ixy="0" ixz="0" iyy="0.4" iyz="0" izz="0.4" />
    </inertial>
  </link>
  <joint name="base_link_to_side1" type="fixed">
    <parent link="base_link" />
    <child link="side1" />
    <origin xyz="0 3.3 -0.4" rpy="0 0 0" />
  </joint>
  <link name="side1">
    <visual>
      <origin xyz="6 0 0" rpy="0 0 0" />
      <geometry>
        <box size="16 0.4 0.4" />
      </geometry>
      <material name="side1-material">
        <color rgba="0.5271151256969157 0.5209955731953768 0.5028864580233624 1" />
      </material>
    </visual>
    <collision>
      <origin xyz="12 0 0" rpy="0 0 0" />
      <geometry>
        <box size="16 0.4 0.4" />
      </geometry>
    </collision>
    <inertial>
      <origin xyz="12 0 0" rpy="0 0 0" />
      <mass value="1" />
      <inertia ixx="0.16666666666666666" ixy="0" ixz="0" iyy="0.16666666666666666" iyz="0" izz="0.16666666666666666" />
    </inertial>
  </link>
  <joint name="base_link_to_side2" type="fixed">
    <parent link="base_link" />
    <child link="side2" />
    <origin xyz="0 -3.3 -0.4" rpy="0 0 0" />
  </joint>
  <link name="side2">
    <visual>
      <origin xyz="6 0 0" rpy="0 0 0" />
      <geometry>
        <box size="16 0.4 0.4" />
      </geometry>
      <material name="side2-material">
        <color rgba="0.5271151256969157 0.5209955731953768 0.5028864580233624 1" />
      </material>
    </visual>
    <collision>
      <origin xyz="12 0 0" rpy="0 0 0" />
      <geometry>
        <box size="16 0.4 0.4" />
      </geometry>
    </collision>
    <inertial>
      <origin xyz="12 0 0" rpy="0 0 0" />
      <mass value="1" />
      <inertia ixx="0.16666666666666666" ixy="0" ixz="0" iyy="0.16666666666666666" iyz="0" izz="0.16666666666666666" />
    </inertial>
  </link>
  <joint name="base_link_to_wheel_right1" type="continuous">
    <parent link="base_link" />
    <child link="wheel_right1" />
    <origin xyz="-1.2 -3 -0.4" rpy="1.5707963267948963 0 0" />
    <axis xyz="0 0 1"/>
  </joint>
  <link name="wheel_right1">
    <visual>
      <origin xyz="0 0 0" rpy="0 0 0" />
      <geometry>
        <cylinder radius="0.6" length="0.2" />
      </geometry>
      <material name="wheel_right1-material">
        <color rgba="0.6375968739867731 0.04373502925049377 0.008023192982520563 1" />
      </material>
    </visual>
    <collision>
      <origin xyz="0 0 0" rpy="0 0 0" />
      <geometry>
        <cylinder radius="0.6" length="0.2" />
      </geometry>
    </collision>
    <inertial>
      <origin xyz="0 0 0" rpy="0 0 0" />
      <mass value="1" />
      <inertia ixx="0.3333333333333333" ixy="0" ixz="0" iyy="0.5" iyz="0" izz="0.3333333333333333" />
    </inertial>
  </link>
  <joint name="base_link_to_omniwheel1" type="fixed">
    <parent link="base_link" />
    <child link="omniwheel1" />
    <origin xyz="13.5 3.3 -0.7" rpy="0 0 0" />
  </joint>
  <link name="omniwheel1">
    <visual>
      <origin xyz="0 0 0" rpy="0 0 0" />
      <geometry>
        <sphere radius="0.2" />
      </geometry>
      <material name="omniwheel1-material">
        <color rgba="0.14702726648767014 0.10461648408208657 0.4969329950515914 1" />
      </material>
    </visual>
    <collision>
      <origin xyz="0 0 0" rpy="0 0 0" />
      <geometry>
        <sphere radius="0.2" />
      </geometry>
    </collision>
    <inertial>
      <origin xyz="0 0 0" rpy="0 0 0" />
      <mass value="1" />
      <inertia ixx="0.4" ixy="0" ixz="0" iyy="0.4" iyz="0" izz="0.4" />
    </inertial>
  </link>
</robot>